2025-07-06 05:09:07 - test_server - INFO - test_server.py:20 - Starting DVSS-PPA application...
2025-07-06 05:09:07 - test_server - ERROR - test_server.py:27 - Failed to create database tables: (psycopg2.OperationalError) connection to server at "localhost" (::1), port 5432 failed: Connection refused
	Is the server running on that host and accepting TCP/IP connections?
connection to server at "localhost" (127.0.0.1), port 5432 failed: Connection refused
	Is the server running on that host and accepting TCP/IP connections?

(Background on this error at: https://sqlalche.me/e/20/e3q8)
2025-07-06 05:09:07 - test_server - WARNING - test_server.py:28 - Application will continue without database
2025-07-06 05:09:07 - test_server - INFO - test_server.py:30 - DVSS-PPA application started successfully
2025-07-06 05:12:23 - test_server - INFO - test_server.py:35 - Shutting down DVSS-PPA application...
2025-07-06 05:13:21 - server - INFO - server.py:133 - All routers registered successfully
2025-07-06 05:13:22 - server - INFO - server.py:133 - All routers registered successfully
2025-07-06 05:13:22 - server - INFO - server.py:133 - All routers registered successfully
2025-07-06 05:13:22 - server - INFO - server.py:29 - Starting DVSS-PPA application...
2025-07-06 05:13:22 - server - ERROR - server.py:36 - Failed to create database tables: (psycopg2.OperationalError) connection to server at "localhost" (::1), port 5432 failed: Connection refused
	Is the server running on that host and accepting TCP/IP connections?
connection to server at "localhost" (127.0.0.1), port 5432 failed: Connection refused
	Is the server running on that host and accepting TCP/IP connections?

(Background on this error at: https://sqlalche.me/e/20/e3q8)
2025-07-06 05:13:38 - server - INFO - server.py:133 - All routers registered successfully
2025-07-06 05:13:38 - server - INFO - server.py:133 - All routers registered successfully
2025-07-06 05:13:38 - server - INFO - server.py:29 - Starting DVSS-PPA application...
2025-07-06 05:13:38 - server - ERROR - server.py:36 - Failed to create database tables: (psycopg2.OperationalError) connection to server at "localhost" (::1), port 5432 failed: Connection refused
	Is the server running on that host and accepting TCP/IP connections?
connection to server at "localhost" (127.0.0.1), port 5432 failed: Connection refused
	Is the server running on that host and accepting TCP/IP connections?

(Background on this error at: https://sqlalche.me/e/20/e3q8)
2025-07-06 05:13:38 - server - WARNING - server.py:37 - Application will continue without database
2025-07-06 05:13:38 - server - ERROR - server.py:45 - Failed to connect to Redis: Error 61 connecting to localhost:6379. Connection refused.
2025-07-06 05:13:38 - server - WARNING - server.py:47 - Application will continue without Redis
2025-07-06 05:13:38 - server - INFO - server.py:49 - DVSS-PPA application started successfully
2025-07-06 05:13:54 - server - INFO - server.py:133 - All routers registered successfully
2025-07-06 05:14:13 - server - INFO - server.py:133 - All routers registered successfully
2025-07-06 05:14:14 - server - INFO - server.py:133 - All routers registered successfully
2025-07-06 05:14:14 - server - INFO - server.py:133 - All routers registered successfully
2025-07-06 05:14:14 - server - INFO - server.py:29 - Starting DVSS-PPA application...
2025-07-06 05:14:14 - server - ERROR - server.py:36 - Failed to create database tables: (psycopg2.OperationalError) connection to server at "localhost" (::1), port 5432 failed: Connection refused
	Is the server running on that host and accepting TCP/IP connections?
connection to server at "localhost" (127.0.0.1), port 5432 failed: Connection refused
	Is the server running on that host and accepting TCP/IP connections?

(Background on this error at: https://sqlalche.me/e/20/e3q8)
2025-07-06 05:14:14 - server - WARNING - server.py:37 - Application will continue without database
2025-07-06 05:14:14 - server - ERROR - server.py:45 - Failed to connect to Redis: Error 61 connecting to localhost:6379. Connection refused.
2025-07-06 05:14:14 - server - WARNING - server.py:47 - Application will continue without Redis
2025-07-06 05:14:14 - server - INFO - server.py:49 - DVSS-PPA application started successfully
2025-07-06 05:15:37 - server - INFO - server.py:54 - Shutting down DVSS-PPA application...
2025-07-06 05:15:38 - server - INFO - server.py:133 - All routers registered successfully
2025-07-06 05:15:38 - server - INFO - server.py:133 - All routers registered successfully
2025-07-06 05:15:38 - server - INFO - server.py:29 - Starting DVSS-PPA application...
2025-07-06 05:15:38 - server - ERROR - server.py:36 - Failed to create database tables: (psycopg2.OperationalError) connection to server at "localhost" (::1), port 5432 failed: Connection refused
	Is the server running on that host and accepting TCP/IP connections?
connection to server at "localhost" (127.0.0.1), port 5432 failed: Connection refused
	Is the server running on that host and accepting TCP/IP connections?

(Background on this error at: https://sqlalche.me/e/20/e3q8)
2025-07-06 05:15:38 - server - WARNING - server.py:37 - Application will continue without database
2025-07-06 05:15:38 - server - ERROR - server.py:45 - Failed to connect to Redis: Error 61 connecting to localhost:6379. Connection refused.
2025-07-06 05:15:38 - server - WARNING - server.py:47 - Application will continue without Redis
2025-07-06 05:15:38 - server - INFO - server.py:49 - DVSS-PPA application started successfully
2025-07-06 05:17:30 - server - INFO - server.py:54 - Shutting down DVSS-PPA application...
2025-07-06 05:17:30 - server - INFO - server.py:133 - All routers registered successfully
2025-07-06 05:17:30 - server - INFO - server.py:133 - All routers registered successfully
2025-07-06 05:17:30 - server - INFO - server.py:29 - Starting DVSS-PPA application...
2025-07-06 05:17:30 - server - ERROR - server.py:36 - Failed to create database tables: (psycopg2.OperationalError) connection to server at "localhost" (::1), port 5432 failed: Connection refused
	Is the server running on that host and accepting TCP/IP connections?
connection to server at "localhost" (127.0.0.1), port 5432 failed: Connection refused
	Is the server running on that host and accepting TCP/IP connections?

(Background on this error at: https://sqlalche.me/e/20/e3q8)
2025-07-06 05:17:30 - server - WARNING - server.py:37 - Application will continue without database
2025-07-06 05:17:30 - server - ERROR - server.py:45 - Failed to connect to Redis: Error 61 connecting to localhost:6379. Connection refused.
2025-07-06 05:17:30 - server - WARNING - server.py:47 - Application will continue without Redis
2025-07-06 05:17:30 - server - INFO - server.py:49 - DVSS-PPA application started successfully
2025-07-06 13:19:14 - server - INFO - server.py:133 - All routers registered successfully
2025-07-06 13:19:15 - server - INFO - server.py:133 - All routers registered successfully
2025-07-06 13:19:15 - server - INFO - server.py:133 - All routers registered successfully
2025-07-06 13:19:15 - server - INFO - server.py:29 - Starting DVSS-PPA application...
2025-07-06 13:19:15 - server - ERROR - server.py:36 - Failed to create database tables: (psycopg2.OperationalError) connection to server at "localhost" (::1), port 5432 failed: Connection refused
	Is the server running on that host and accepting TCP/IP connections?
connection to server at "localhost" (127.0.0.1), port 5432 failed: Connection refused
	Is the server running on that host and accepting TCP/IP connections?

(Background on this error at: https://sqlalche.me/e/20/e3q8)
2025-07-06 13:19:15 - server - WARNING - server.py:37 - Application will continue without database
2025-07-06 13:19:15 - server - ERROR - server.py:45 - Failed to connect to Redis: Error 61 connecting to localhost:6379. Connection refused.
2025-07-06 13:19:15 - server - WARNING - server.py:47 - Application will continue without Redis
2025-07-06 13:19:15 - server - INFO - server.py:49 - DVSS-PPA application started successfully
2025-07-06 13:20:14 - user_dao - ERROR - user_dao.py:168 - Get all users error: (psycopg2.OperationalError) connection to server at "localhost" (::1), port 5432 failed: Connection refused
	Is the server running on that host and accepting TCP/IP connections?
connection to server at "localhost" (127.0.0.1), port 5432 failed: Connection refused
	Is the server running on that host and accepting TCP/IP connections?

(Background on this error at: https://sqlalche.me/e/20/e3q8)
2025-07-06 13:20:14 - user_controller - ERROR - user_controller.py:66 - Error getting users: 获取用户列表失败: (psycopg2.OperationalError) connection to server at "localhost" (::1), port 5432 failed: Connection refused
	Is the server running on that host and accepting TCP/IP connections?
connection to server at "localhost" (127.0.0.1), port 5432 failed: Connection refused
	Is the server running on that host and accepting TCP/IP connections?

(Background on this error at: https://sqlalche.me/e/20/e3q8)
2025-07-06 13:20:14 - exception_handler - ERROR - handle.py:86 - Unhandled Exception: type object 'ResponseUtil' has no attribute 'server_error'
Traceback (most recent call last):
  File "/Users/liuyue/.pyenv/versions/3.12.3/lib/python3.12/site-packages/anyio/streams/memory.py", line 98, in receive
    return self.receive_nowait()
           ^^^^^^^^^^^^^^^^^^^^^
  File "/Users/liuyue/.pyenv/versions/3.12.3/lib/python3.12/site-packages/anyio/streams/memory.py", line 93, in receive_nowait
    raise WouldBlock
anyio.WouldBlock

During handling of the above exception, another exception occurred:

Traceback (most recent call last):
  File "/Users/liuyue/.pyenv/versions/3.12.3/lib/python3.12/site-packages/starlette/middleware/base.py", line 78, in call_next
    message = await recv_stream.receive()
              ^^^^^^^^^^^^^^^^^^^^^^^^^^^
  File "/Users/liuyue/.pyenv/versions/3.12.3/lib/python3.12/site-packages/anyio/streams/memory.py", line 118, in receive
    raise EndOfStream
anyio.EndOfStream

During handling of the above exception, another exception occurred:

Traceback (most recent call last):
  File "/Users/liuyue/.pyenv/versions/3.12.3/lib/python3.12/site-packages/starlette/middleware/errors.py", line 162, in __call__
    await self.app(scope, receive, _send)
  File "/Users/liuyue/.pyenv/versions/3.12.3/lib/python3.12/site-packages/starlette/middleware/base.py", line 108, in __call__
    response = await self.dispatch_func(request, call_next)
               ^^^^^^^^^^^^^^^^^^^^^^^^^^^^^^^^^^^^^^^^^^^^
  File "/Users/liuyue/code/Shan-Yingqing-UUM-PhD-2025-V0126/dvss-ppa-implementation/backend-python/middlewares/auth_middleware.py", line 35, in dispatch
    response = await call_next(request)
               ^^^^^^^^^^^^^^^^^^^^^^^^
  File "/Users/liuyue/.pyenv/versions/3.12.3/lib/python3.12/site-packages/starlette/middleware/base.py", line 84, in call_next
    raise app_exc
  File "/Users/liuyue/.pyenv/versions/3.12.3/lib/python3.12/site-packages/starlette/middleware/base.py", line 70, in coro
    await self.app(scope, receive_or_disconnect, send_no_error)
  File "/Users/liuyue/.pyenv/versions/3.12.3/lib/python3.12/site-packages/starlette/middleware/gzip.py", line 26, in __call__
    await self.app(scope, receive, send)
  File "/Users/liuyue/.pyenv/versions/3.12.3/lib/python3.12/site-packages/starlette/middleware/cors.py", line 83, in __call__
    await self.app(scope, receive, send)
  File "/Users/liuyue/.pyenv/versions/3.12.3/lib/python3.12/site-packages/starlette/middleware/exceptions.py", line 79, in __call__
    raise exc
  File "/Users/liuyue/.pyenv/versions/3.12.3/lib/python3.12/site-packages/starlette/middleware/exceptions.py", line 68, in __call__
    await self.app(scope, receive, sender)
  File "/Users/liuyue/.pyenv/versions/3.12.3/lib/python3.12/site-packages/fastapi/middleware/asyncexitstack.py", line 20, in __call__
    raise e
  File "/Users/liuyue/.pyenv/versions/3.12.3/lib/python3.12/site-packages/fastapi/middleware/asyncexitstack.py", line 17, in __call__
    await self.app(scope, receive, send)
  File "/Users/liuyue/.pyenv/versions/3.12.3/lib/python3.12/site-packages/starlette/routing.py", line 718, in __call__
    await route.handle(scope, receive, send)
  File "/Users/liuyue/.pyenv/versions/3.12.3/lib/python3.12/site-packages/starlette/routing.py", line 276, in handle
    await self.app(scope, receive, send)
  File "/Users/liuyue/.pyenv/versions/3.12.3/lib/python3.12/site-packages/starlette/routing.py", line 66, in app
    response = await func(request)
               ^^^^^^^^^^^^^^^^^^^
  File "/Users/liuyue/.pyenv/versions/3.12.3/lib/python3.12/site-packages/fastapi/routing.py", line 274, in app
    raw_response = await run_endpoint_function(
                   ^^^^^^^^^^^^^^^^^^^^^^^^^^^^
  File "/Users/liuyue/.pyenv/versions/3.12.3/lib/python3.12/site-packages/fastapi/routing.py", line 193, in run_endpoint_function
    return await run_in_threadpool(dependant.call, **values)
           ^^^^^^^^^^^^^^^^^^^^^^^^^^^^^^^^^^^^^^^^^^^^^^^^^
  File "/Users/liuyue/.pyenv/versions/3.12.3/lib/python3.12/site-packages/starlette/concurrency.py", line 41, in run_in_threadpool
    return await anyio.to_thread.run_sync(func, *args)
           ^^^^^^^^^^^^^^^^^^^^^^^^^^^^^^^^^^^^^^^^^^^
  File "/Users/liuyue/.pyenv/versions/3.12.3/lib/python3.12/site-packages/anyio/to_thread.py", line 33, in run_sync
    return await get_asynclib().run_sync_in_worker_thread(
           ^^^^^^^^^^^^^^^^^^^^^^^^^^^^^^^^^^^^^^^^^^^^^^^
  File "/Users/liuyue/.pyenv/versions/3.12.3/lib/python3.12/site-packages/anyio/_backends/_asyncio.py", line 877, in run_sync_in_worker_thread
    return await future
           ^^^^^^^^^^^^
  File "/Users/liuyue/.pyenv/versions/3.12.3/lib/python3.12/site-packages/anyio/_backends/_asyncio.py", line 807, in run
    result = context.run(func, *args)
             ^^^^^^^^^^^^^^^^^^^^^^^^
  File "/Users/liuyue/code/Shan-Yingqing-UUM-PhD-2025-V0126/dvss-ppa-implementation/backend-python/module_dvss/controller/user_controller.py", line 67, in get_users
    return ResponseUtil.server_error("获取用户列表失败")
           ^^^^^^^^^^^^^^^^^^^^^^^^^
AttributeError: type object 'ResponseUtil' has no attribute 'server_error'
